<?xml version='1.0'?>

<robot name="aibot" xmlns:xacro="http://ros.org/wiki/xacro">

  <link name='base_link' />

  <link name='base_footprint'>

    <visual name='base_footprint_visual'>
      <origin xyz="0 0 0" rpy="0 0 0"/>
      <geometry>
        <mesh filename="package://aibot_description/meshes/myagv_pro/car_body.stl" scale="0.001 0.001 0.001"/>
      </geometry>
    </visual>

    <collision name='collision_body'>
    <origin xyz="0 0 0.15" rpy="0 0 0"/>
      <geometry>
        <box size="0.40 0.55 0.3"/>
      </geometry>
    </collision>

  </link>

  <joint name="base_footprint_joint" type="fixed" >
    <origin xyz="0 0 0.019" rpy="0 0 -1.57"/>
    <child link="base_footprint"/>
    <parent link="base_link"/>
  </joint>

  <link name="left_wheel">

    <visual name="left_wheel_visual">
      <origin xyz="0 0 0" rpy="0 1.5707 0"/>
      <geometry>
        <cylinder radius="0.1025" length="0.04"/>
      </geometry>
    </visual>

    <collision name="collision_left_wheel">
      <origin xyz="0 0 0" rpy="0 1.5707 0"/>
      <geometry>
        <cylinder radius="0.1025" length="0.04"/>
      </geometry>
    </collision>

  </link>

  <link name="right_wheel">

    <visual name="right_wheel_visual">
      <origin xyz="0 0 0.0" rpy="0 1.5707 0"/>
      <geometry>
        <cylinder radius="0.1025" length="0.04"/>
      </geometry>
    </visual>

    <collision name="collision_right_wheel">
      <origin xyz="0 0 0" rpy="0 1.5707 0"/>
      <geometry>
        <cylinder radius="0.1025" length="0.04"/>
      </geometry>
    </collision>

  </link>

  <joint name="left_wheel_joint" type="continuous">
    <origin xyz="0.1425 0 0.081" rpy="0 0 0"/>
    <child link="left_wheel"/>
    <parent link="base_footprint"/>
    <axis xyz="0 1 0" />
    <limit effort="10000" velocity="1000"/>
    <joint_properties damping="1.0" friction="1.0"/>
  </joint>

  <joint name="right_wheel_joint" type="continuous">
    <origin xyz="-0.1425 0 0.081" rpy="0 0 0"/>
    <child link="right_wheel"/>
    <parent link="base_footprint"/>
    <axis xyz="0 1 0" rpy="0 0 0"/>
    <limit effort="10000" velocity="1000"/>
    <joint_properties damping="1.0" friction="1.0"/>
  </joint>


  <link name="rear_wheel">

    <visual name="rear_wheel_visual">
      <origin xyz="0 0 0" rpy="0 1.5707 0"/>
      <geometry>
        <cylinder radius="0.04" length="0.03"/>
      </geometry>
    </visual>

    <collision name="collision_rear_wheel">
      <origin xyz="0 0 0" rpy="0 1.5707 0"/>
      <geometry>
        <cylinder radius="0.04" length="0.03"/>
      </geometry>
    </collision>

  </link>

  <link name="front_wheel">

    <visual name="front_wheel_visual">
      <origin xyz="0 0 0" rpy="0 1.5707 0"/>
      <geometry>
        <cylinder radius="0.04" length="0.03"/>
      </geometry>
    </visual>

    <collision name="collision_front_wheel">
      <origin xyz="0 0 0" rpy="0 1.5707 0"/>
      <geometry>
        <cylinder radius="0.04" length="0.03"/>
      </geometry>
    </collision>
 
  </link>

  <joint name="rear_wheel_joint" type="continuous">
    <origin xyz="0 0.175 0.019" rpy="0 0 0"/>
    <child link="rear_wheel"/>
    <parent link="base_footprint"/>
    <axis xyz="0 1 0" rpy="0 0 0"/>
    <limit effort="10000" velocity="1000"/>
    <joint_properties damping="1.0" friction="1.0"/>
  </joint>

  <joint name="front_wheel_joint" type="continuous">
    <origin xyz="0 -0.175 0.019" rpy="0 0 0"/>
    <child link="front_wheel"/>
    <parent link="base_footprint"/>
    <axis xyz="0 1 0" rpy="0 0 0"/>
    <limit effort="10000" velocity="1000"/>
    <joint_properties damping="1.0" friction="1.0"/>
  </joint>


  <link name="camera">

    <visual name="camera_visual">
      <origin xyz="0 0 0" rpy="0 0 0"/>
      <geometry>
        <cylinder radius="0.005" length="0.005"/>
      </geometry>
      <material name="black"/>
    </visual>

    <collision name="collision_camera">
      <origin xyz="0 0 0" rpy="0 0 0"/>
      <geometry>
        <cylinder radius="0.005" length="0.005"/>
      </geometry>
    </collision>

  </link>

  <joint name="camera_joint" type="fixed">
    <origin xyz="0 0.275 0.1" rpy="1.57 0 1.57"/>
    <parent link="base_footprint"/>
    <child link="camera"/>
  </joint>

  <link name="laser">

    <visual name="laser_visual">
      <origin xyz="0 0 0" rpy="0 0 0"/>
      <geometry>
        <cylinder radius="0.036" length="0.045"/>
      </geometry>
      <material name="green_black"/>
    </visual>

    <collision name="collision_laser">
      <origin xyz="0 0 0" rpy="0 0 0"/>
      <geometry>
        <cylinder radius="0.036" length="0.045"/>
      </geometry>
    </collision>

  </link>

  <joint name="laser_joint" type="fixed">
    <axis xyz="0 1 0" />
    <origin xyz="0 0.21 0.18" rpy="0 0 -0.91"/>
    <parent link="base_footprint"/>
    <child link="laser"/>
  </joint>

  <link name="imu_link">

    <visual name="imu_visual">
      <origin xyz="0 0 0" rpy="0 0 0"/>
      <geometry>
        <cylinder radius="0.001" length="0.001"/>
      </geometry>
      <material name="black"/>
    </visual>

  </link>

  <joint name="imu_joint" type="fixed">
    <origin xyz="-0.056 -0.045 0.13" rpy="0 0 1.57"/>
    <parent link="base_footprint"/>
    <child link="imu_link"/>
  </joint>


  <!-- <link name="extend_back_link">
    <visual name="extend_visual">
      <origin xyz="0 0 0" rpy="0 0 0"/>
      <geometry>
        <cylinder radius="0.001" length="0.001"/>
      </geometry>
      <material name="green_black"/>
    </visual>
  </link>

  <joint name="extend_back_link_joint" type="fixed">
    <origin xyz="-0.0705 0 0.084" rpy="0 0 0"/>
    <parent link="base_footprint"/>
    <child link="extend_back_link"/>
  </joint>

  <link name="extend_front_link">

    <visual name="extend_visual">
      <origin xyz="0 0 0" rpy="0 0 0"/>
      <geometry>
        <cylinder radius="0.001" length="0.001"/>
      </geometry>
      <material name="green_black"/>
    </visual>

  </link>

  <joint name="extend_front_link_joint" type="fixed">
    <origin xyz="0.0695 0 0.154" rpy="0 0 0"/>
    <parent link="base_footprint"/>
    <child link="extend_front_link"/>
  </joint> -->


</robot>
